[2025-08-16T19:31:16.667+0000] {local_task_job_runner.py:120} INFO - ::group::Pre task execution logs
[2025-08-16T19:31:16.697+0000] {taskinstance.py:2076} INFO - Dependencies all met for dep_context=non-requeueable deps ti=<TaskInstance: orders_pipeline.upload_to_s3 manual__2025-08-16T19:26:10+00:00 [queued]>
[2025-08-16T19:31:16.706+0000] {taskinstance.py:2076} INFO - Dependencies all met for dep_context=requeueable deps ti=<TaskInstance: orders_pipeline.upload_to_s3 manual__2025-08-16T19:26:10+00:00 [queued]>
[2025-08-16T19:31:16.707+0000] {taskinstance.py:2306} INFO - Starting attempt 2 of 2
[2025-08-16T19:31:16.724+0000] {taskinstance.py:2330} INFO - Executing <Task(BashOperator): upload_to_s3> on 2025-08-16 19:26:10+00:00
[2025-08-16T19:31:16.730+0000] {standard_task_runner.py:64} INFO - Started process 116 to run task
[2025-08-16T19:31:16.735+0000] {standard_task_runner.py:90} INFO - Running: ['***', 'tasks', 'run', 'orders_pipeline', 'upload_to_s3', 'manual__2025-08-16T19:26:10+00:00', '--job-id', '71', '--raw', '--subdir', 'DAGS_FOLDER/orders_pipeline.py', '--cfg-path', '/tmp/tmph_ppz848']
[2025-08-16T19:31:16.737+0000] {standard_task_runner.py:91} INFO - Job 71: Subtask upload_to_s3
[2025-08-16T19:31:16.815+0000] {task_command.py:426} INFO - Running <TaskInstance: orders_pipeline.upload_to_s3 manual__2025-08-16T19:26:10+00:00 [running]> on host 392a94efd1c1
[2025-08-16T19:31:16.955+0000] {taskinstance.py:2648} INFO - Exporting env vars: AIRFLOW_CTX_DAG_OWNER='***' AIRFLOW_CTX_DAG_ID='orders_pipeline' AIRFLOW_CTX_TASK_ID='upload_to_s3' AIRFLOW_CTX_EXECUTION_DATE='2025-08-16T19:26:10+00:00' AIRFLOW_CTX_TRY_NUMBER='2' AIRFLOW_CTX_DAG_RUN_ID='manual__2025-08-16T19:26:10+00:00'
[2025-08-16T19:31:16.956+0000] {taskinstance.py:430} INFO - ::endgroup::
[2025-08-16T19:31:16.972+0000] {subprocess.py:63} INFO - Tmp dir root location: /tmp
[2025-08-16T19:31:16.973+0000] {subprocess.py:75} INFO - Running command: ['/usr/bin/bash', '-c', 'set -Eeuo pipefail -x; test -f /tmp/orders.csv\naws s3 cp /tmp/orders.csv s3://$S3_BUCKET/raw-data/orders/orders.csv --content-type text/csv\naws s3 ls s3://$S3_BUCKET/raw-data/orders/ || true']
[2025-08-16T19:31:16.986+0000] {subprocess.py:86} INFO - Output:
[2025-08-16T19:31:16.987+0000] {subprocess.py:93} INFO - + test -f /tmp/orders.csv
[2025-08-16T19:31:16.987+0000] {subprocess.py:93} INFO - + aws s3 cp /tmp/orders.csv s3://pt-data-lab/raw-data/orders/orders.csv --content-type text/csv
[2025-08-16T19:31:18.672+0000] {subprocess.py:93} INFO - Completed 133 Bytes/133 Bytes (198 Bytes/s) with 1 file(s) remainingupload failed: ../orders.csv to s3://pt-data-lab/raw-data/orders/orders.csv An error occurred (AccessDenied) when calling the PutObject operation: User: arn:aws:iam::657552582906:user/***-dbt-dev is not authorized to perform: s3:PutObject on resource: "arn:aws:s3:::pt-data-lab/raw-data/orders/orders.csv" because no identity-based policy allows the s3:PutObject action
[2025-08-16T19:31:18.770+0000] {subprocess.py:97} INFO - Command exited with return code 1
[2025-08-16T19:31:18.771+0000] {taskinstance.py:441} INFO - ::group::Post task execution logs
[2025-08-16T19:31:18.788+0000] {taskinstance.py:2905} ERROR - Task failed with exception
Traceback (most recent call last):
  File "/home/airflow/.local/lib/python3.11/site-packages/airflow/models/taskinstance.py", line 460, in _execute_task
    result = _execute_callable(context=context, **execute_callable_kwargs)
             ^^^^^^^^^^^^^^^^^^^^^^^^^^^^^^^^^^^^^^^^^^^^^^^^^^^^^^^^^^^^^
  File "/home/airflow/.local/lib/python3.11/site-packages/airflow/models/taskinstance.py", line 432, in _execute_callable
    return execute_callable(context=context, **execute_callable_kwargs)
           ^^^^^^^^^^^^^^^^^^^^^^^^^^^^^^^^^^^^^^^^^^^^^^^^^^^^^^^^^^^^
  File "/home/airflow/.local/lib/python3.11/site-packages/airflow/models/baseoperator.py", line 401, in wrapper
    return func(self, *args, **kwargs)
           ^^^^^^^^^^^^^^^^^^^^^^^^^^^
  File "/home/airflow/.local/lib/python3.11/site-packages/airflow/operators/bash.py", line 243, in execute
    raise AirflowException(
airflow.exceptions.AirflowException: Bash command failed. The command returned a non-zero exit code 1.
[2025-08-16T19:31:18.793+0000] {taskinstance.py:1206} INFO - Marking task as FAILED. dag_id=orders_pipeline, task_id=upload_to_s3, run_id=manual__2025-08-16T19:26:10+00:00, execution_date=20250816T192610, start_date=20250816T193116, end_date=20250816T193118
[2025-08-16T19:31:18.812+0000] {standard_task_runner.py:110} ERROR - Failed to execute job 71 for task upload_to_s3 (Bash command failed. The command returned a non-zero exit code 1.; 116)
[2025-08-16T19:31:18.844+0000] {local_task_job_runner.py:243} INFO - Task exited with return code 1
[2025-08-16T19:31:18.874+0000] {taskinstance.py:3503} INFO - 0 downstream tasks scheduled from follow-on schedule check
[2025-08-16T19:31:18.880+0000] {local_task_job_runner.py:222} INFO - ::endgroup::
