[2025-08-16T19:26:13.517+0000] {local_task_job_runner.py:120} INFO - ::group::Pre task execution logs
[2025-08-16T19:26:13.555+0000] {taskinstance.py:2076} INFO - Dependencies all met for dep_context=non-requeueable deps ti=<TaskInstance: orders_pipeline.upload_to_s3 manual__2025-08-16T19:26:10+00:00 [queued]>
[2025-08-16T19:26:13.568+0000] {taskinstance.py:2076} INFO - Dependencies all met for dep_context=requeueable deps ti=<TaskInstance: orders_pipeline.upload_to_s3 manual__2025-08-16T19:26:10+00:00 [queued]>
[2025-08-16T19:26:13.569+0000] {taskinstance.py:2306} INFO - Starting attempt 1 of 2
[2025-08-16T19:26:13.586+0000] {taskinstance.py:2330} INFO - Executing <Task(BashOperator): upload_to_s3> on 2025-08-16 19:26:10+00:00
[2025-08-16T19:26:13.592+0000] {standard_task_runner.py:64} INFO - Started process 222 to run task
[2025-08-16T19:26:13.597+0000] {standard_task_runner.py:90} INFO - Running: ['***', 'tasks', 'run', 'orders_pipeline', 'upload_to_s3', 'manual__2025-08-16T19:26:10+00:00', '--job-id', '60', '--raw', '--subdir', 'DAGS_FOLDER/orders_pipeline.py', '--cfg-path', '/tmp/tmp3ky2jwmv']
[2025-08-16T19:26:13.599+0000] {standard_task_runner.py:91} INFO - Job 60: Subtask upload_to_s3
[2025-08-16T19:26:13.671+0000] {task_command.py:426} INFO - Running <TaskInstance: orders_pipeline.upload_to_s3 manual__2025-08-16T19:26:10+00:00 [running]> on host 392a94efd1c1
[2025-08-16T19:26:13.848+0000] {taskinstance.py:2648} INFO - Exporting env vars: AIRFLOW_CTX_DAG_OWNER='***' AIRFLOW_CTX_DAG_ID='orders_pipeline' AIRFLOW_CTX_TASK_ID='upload_to_s3' AIRFLOW_CTX_EXECUTION_DATE='2025-08-16T19:26:10+00:00' AIRFLOW_CTX_TRY_NUMBER='1' AIRFLOW_CTX_DAG_RUN_ID='manual__2025-08-16T19:26:10+00:00'
[2025-08-16T19:26:13.849+0000] {taskinstance.py:430} INFO - ::endgroup::
[2025-08-16T19:26:13.869+0000] {subprocess.py:63} INFO - Tmp dir root location: /tmp
[2025-08-16T19:26:13.870+0000] {subprocess.py:75} INFO - Running command: ['/usr/bin/bash', '-c', 'set -Eeuo pipefail -x; test -f /tmp/orders.csv\naws s3 cp /tmp/orders.csv s3://$S3_BUCKET/raw-data/orders/orders.csv --content-type text/csv\naws s3 ls s3://$S3_BUCKET/raw-data/orders/ || true']
[2025-08-16T19:26:13.887+0000] {subprocess.py:86} INFO - Output:
[2025-08-16T19:26:13.889+0000] {subprocess.py:93} INFO - + test -f /tmp/orders.csv
[2025-08-16T19:26:13.890+0000] {subprocess.py:93} INFO - + aws s3 cp /tmp/orders.csv s3://pt-data-lab/raw-data/orders/orders.csv --content-type text/csv
[2025-08-16T19:26:15.846+0000] {subprocess.py:93} INFO - Completed 133 Bytes/133 Bytes (173 Bytes/s) with 1 file(s) remainingupload failed: ../orders.csv to s3://pt-data-lab/raw-data/orders/orders.csv An error occurred (AccessDenied) when calling the PutObject operation: User: arn:aws:iam::657552582906:user/***-dbt-dev is not authorized to perform: s3:PutObject on resource: "arn:aws:s3:::pt-data-lab/raw-data/orders/orders.csv" because no identity-based policy allows the s3:PutObject action
[2025-08-16T19:26:15.936+0000] {subprocess.py:97} INFO - Command exited with return code 1
[2025-08-16T19:26:15.937+0000] {taskinstance.py:441} INFO - ::group::Post task execution logs
[2025-08-16T19:26:15.954+0000] {taskinstance.py:2905} ERROR - Task failed with exception
Traceback (most recent call last):
  File "/home/airflow/.local/lib/python3.11/site-packages/airflow/models/taskinstance.py", line 460, in _execute_task
    result = _execute_callable(context=context, **execute_callable_kwargs)
             ^^^^^^^^^^^^^^^^^^^^^^^^^^^^^^^^^^^^^^^^^^^^^^^^^^^^^^^^^^^^^
  File "/home/airflow/.local/lib/python3.11/site-packages/airflow/models/taskinstance.py", line 432, in _execute_callable
    return execute_callable(context=context, **execute_callable_kwargs)
           ^^^^^^^^^^^^^^^^^^^^^^^^^^^^^^^^^^^^^^^^^^^^^^^^^^^^^^^^^^^^
  File "/home/airflow/.local/lib/python3.11/site-packages/airflow/models/baseoperator.py", line 401, in wrapper
    return func(self, *args, **kwargs)
           ^^^^^^^^^^^^^^^^^^^^^^^^^^^
  File "/home/airflow/.local/lib/python3.11/site-packages/airflow/operators/bash.py", line 243, in execute
    raise AirflowException(
airflow.exceptions.AirflowException: Bash command failed. The command returned a non-zero exit code 1.
[2025-08-16T19:26:15.961+0000] {taskinstance.py:1206} INFO - Marking task as UP_FOR_RETRY. dag_id=orders_pipeline, task_id=upload_to_s3, run_id=manual__2025-08-16T19:26:10+00:00, execution_date=20250816T192610, start_date=20250816T192613, end_date=20250816T192615
[2025-08-16T19:26:15.979+0000] {standard_task_runner.py:110} ERROR - Failed to execute job 60 for task upload_to_s3 (Bash command failed. The command returned a non-zero exit code 1.; 222)
[2025-08-16T19:26:16.029+0000] {local_task_job_runner.py:243} INFO - Task exited with return code 1
[2025-08-16T19:26:16.060+0000] {taskinstance.py:3503} INFO - 0 downstream tasks scheduled from follow-on schedule check
[2025-08-16T19:26:16.063+0000] {local_task_job_runner.py:222} INFO - ::endgroup::
