[2025-08-13T19:00:23.988+0000] {local_task_job_runner.py:120} INFO - ::group::Pre task execution logs
[2025-08-13T19:00:24.011+0000] {taskinstance.py:2076} INFO - Dependencies all met for dep_context=non-requeueable deps ti=<TaskInstance: orders_pipeline.upload_csv_to_s3 manual__2025-08-13T19:00:11.836772+00:00 [queued]>
[2025-08-13T19:00:24.020+0000] {taskinstance.py:2076} INFO - Dependencies all met for dep_context=requeueable deps ti=<TaskInstance: orders_pipeline.upload_csv_to_s3 manual__2025-08-13T19:00:11.836772+00:00 [queued]>
[2025-08-13T19:00:24.020+0000] {taskinstance.py:2306} INFO - Starting attempt 1 of 1
[2025-08-13T19:00:24.260+0000] {taskinstance.py:2330} INFO - Executing <Task(PythonOperator): upload_csv_to_s3> on 2025-08-13 19:00:11.836772+00:00
[2025-08-13T19:00:24.265+0000] {standard_task_runner.py:64} INFO - Started process 56 to run task
[2025-08-13T19:00:24.269+0000] {standard_task_runner.py:90} INFO - Running: ['***', 'tasks', 'run', 'orders_pipeline', 'upload_csv_to_s3', 'manual__2025-08-13T19:00:11.836772+00:00', '--job-id', '4', '--raw', '--subdir', 'DAGS_FOLDER/orders_pipeline.py', '--cfg-path', '/tmp/tmpzb44q44v']
[2025-08-13T19:00:24.271+0000] {standard_task_runner.py:91} INFO - Job 4: Subtask upload_csv_to_s3
[2025-08-13T19:00:24.615+0000] {task_command.py:426} INFO - Running <TaskInstance: orders_pipeline.upload_csv_to_s3 manual__2025-08-13T19:00:11.836772+00:00 [running]> on host 17d192fb6ef1
[2025-08-13T19:00:25.021+0000] {taskinstance.py:2648} INFO - Exporting env vars: AIRFLOW_CTX_DAG_OWNER='data-eng' AIRFLOW_CTX_DAG_ID='orders_pipeline' AIRFLOW_CTX_TASK_ID='upload_csv_to_s3' AIRFLOW_CTX_EXECUTION_DATE='2025-08-13T19:00:11.836772+00:00' AIRFLOW_CTX_TRY_NUMBER='1' AIRFLOW_CTX_DAG_RUN_ID='manual__2025-08-13T19:00:11.836772+00:00'
[2025-08-13T19:00:25.022+0000] {taskinstance.py:430} INFO - ::endgroup::
[2025-08-13T19:00:25.067+0000] {credentials.py:1147} INFO - Found credentials in environment variables.
[2025-08-13T19:00:44.230+0000] {taskinstance.py:441} INFO - ::group::Post task execution logs
[2025-08-13T19:00:44.231+0000] {taskinstance.py:2905} ERROR - Task failed with exception
Traceback (most recent call last):
  File "/home/airflow/.local/lib/python3.11/site-packages/airflow/models/taskinstance.py", line 465, in _execute_task
    result = _execute_callable(context=context, **execute_callable_kwargs)
             ^^^^^^^^^^^^^^^^^^^^^^^^^^^^^^^^^^^^^^^^^^^^^^^^^^^^^^^^^^^^^
  File "/home/airflow/.local/lib/python3.11/site-packages/airflow/models/taskinstance.py", line 432, in _execute_callable
    return execute_callable(context=context, **execute_callable_kwargs)
           ^^^^^^^^^^^^^^^^^^^^^^^^^^^^^^^^^^^^^^^^^^^^^^^^^^^^^^^^^^^^
  File "/home/airflow/.local/lib/python3.11/site-packages/airflow/models/baseoperator.py", line 401, in wrapper
    return func(self, *args, **kwargs)
           ^^^^^^^^^^^^^^^^^^^^^^^^^^^
  File "/home/airflow/.local/lib/python3.11/site-packages/airflow/operators/python.py", line 235, in execute
    return_value = self.execute_callable()
                   ^^^^^^^^^^^^^^^^^^^^^^^
  File "/home/airflow/.local/lib/python3.11/site-packages/airflow/operators/python.py", line 252, in execute_callable
    return self.python_callable(*self.op_args, **self.op_kwargs)
           ^^^^^^^^^^^^^^^^^^^^^^^^^^^^^^^^^^^^^^^^^^^^^^^^^^^^^
  File "/opt/airflow/dags/orders_pipeline.py", line 28, in upload_csv_to_s3
    s3.upload_file(local, BUCKET, RAW_KEY)
  File "/home/airflow/.local/lib/python3.11/site-packages/boto3/s3/inject.py", line 145, in upload_file
    return transfer.upload_file(
           ^^^^^^^^^^^^^^^^^^^^^
  File "/home/airflow/.local/lib/python3.11/site-packages/boto3/s3/transfer.py", line 372, in upload_file
    future.result()
  File "/home/airflow/.local/lib/python3.11/site-packages/s3transfer/futures.py", line 103, in result
    return self._coordinator.result()
           ^^^^^^^^^^^^^^^^^^^^^^^^^^
  File "/home/airflow/.local/lib/python3.11/site-packages/s3transfer/futures.py", line 266, in result
    raise self._exception
  File "/home/airflow/.local/lib/python3.11/site-packages/s3transfer/tasks.py", line 139, in __call__
    return self._execute_main(kwargs)
           ^^^^^^^^^^^^^^^^^^^^^^^^^^
  File "/home/airflow/.local/lib/python3.11/site-packages/s3transfer/tasks.py", line 162, in _execute_main
    return_value = self._main(**kwargs)
                   ^^^^^^^^^^^^^^^^^^^^
  File "/home/airflow/.local/lib/python3.11/site-packages/s3transfer/upload.py", line 764, in _main
    client.put_object(Bucket=bucket, Key=key, Body=body, **extra_args)
  File "/home/airflow/.local/lib/python3.11/site-packages/botocore/client.py", line 565, in _api_call
    return self._make_api_call(operation_name, kwargs)
           ^^^^^^^^^^^^^^^^^^^^^^^^^^^^^^^^^^^^^^^^^^^
  File "/home/airflow/.local/lib/python3.11/site-packages/botocore/client.py", line 958, in _make_api_call
    api_params = self._emit_api_params(
                 ^^^^^^^^^^^^^^^^^^^^^^
  File "/home/airflow/.local/lib/python3.11/site-packages/botocore/client.py", line 1084, in _emit_api_params
    self.meta.events.emit(
  File "/home/airflow/.local/lib/python3.11/site-packages/botocore/hooks.py", line 412, in emit
    return self._emitter.emit(aliased_event_name, **kwargs)
           ^^^^^^^^^^^^^^^^^^^^^^^^^^^^^^^^^^^^^^^^^^^^^^^^
  File "/home/airflow/.local/lib/python3.11/site-packages/botocore/hooks.py", line 256, in emit
    return self._emit(event_name, kwargs)
           ^^^^^^^^^^^^^^^^^^^^^^^^^^^^^^
  File "/home/airflow/.local/lib/python3.11/site-packages/botocore/hooks.py", line 239, in _emit
    response = handler(**kwargs)
               ^^^^^^^^^^^^^^^^^
  File "/home/airflow/.local/lib/python3.11/site-packages/botocore/handlers.py", line 288, in validate_bucket_name
    raise ParamValidationError(report=error_msg)
botocore.exceptions.ParamValidationError: Parameter validation failed:
Invalid bucket name "pt-data-lab-<seu_sufixo>": Bucket name must match the regex "^[a-zA-Z0-9.\-_]{1,255}$" or be an ARN matching the regex "^arn:(aws).*:(s3|s3-object-lambda):[a-z\-0-9]*:[0-9]{12}:accesspoint[/:][a-zA-Z0-9\-.]{1,63}$|^arn:(aws).*:s3-outposts:[a-z\-0-9]+:[0-9]{12}:outpost[/:][a-zA-Z0-9\-]{1,63}[/:]accesspoint[/:][a-zA-Z0-9\-]{1,63}$"
[2025-08-13T19:00:44.253+0000] {taskinstance.py:1206} INFO - Marking task as FAILED. dag_id=orders_pipeline, task_id=upload_csv_to_s3, run_id=manual__2025-08-13T19:00:11.836772+00:00, execution_date=20250813T190011, start_date=20250813T190024, end_date=20250813T190044
[2025-08-13T19:00:44.420+0000] {standard_task_runner.py:110} ERROR - Failed to execute job 4 for task upload_csv_to_s3 (Parameter validation failed:
Invalid bucket name "pt-data-lab-<seu_sufixo>": Bucket name must match the regex "^[a-zA-Z0-9.\-_]{1,255}$" or be an ARN matching the regex "^arn:(aws).*:(s3|s3-object-lambda):[a-z\-0-9]*:[0-9]{12}:accesspoint[/:][a-zA-Z0-9\-.]{1,63}$|^arn:(aws).*:s3-outposts:[a-z\-0-9]+:[0-9]{12}:outpost[/:][a-zA-Z0-9\-]{1,63}[/:]accesspoint[/:][a-zA-Z0-9\-]{1,63}$"; 56)
[2025-08-13T19:00:44.584+0000] {local_task_job_runner.py:243} INFO - Task exited with return code 1
[2025-08-13T19:00:44.627+0000] {taskinstance.py:3503} INFO - 0 downstream tasks scheduled from follow-on schedule check
[2025-08-13T19:00:44.779+0000] {local_task_job_runner.py:222} INFO - ::endgroup::
