[2025-08-16T19:16:24.787+0000] {local_task_job_runner.py:120} INFO - ::group::Pre task execution logs
[2025-08-16T19:16:24.848+0000] {taskinstance.py:2076} INFO - Dependencies all met for dep_context=non-requeueable deps ti=<TaskInstance: orders_pipeline.upload_to_s3 manual__2025-08-16T19:16:20+00:00 [queued]>
[2025-08-16T19:16:24.863+0000] {taskinstance.py:2076} INFO - Dependencies all met for dep_context=requeueable deps ti=<TaskInstance: orders_pipeline.upload_to_s3 manual__2025-08-16T19:16:20+00:00 [queued]>
[2025-08-16T19:16:24.864+0000] {taskinstance.py:2306} INFO - Starting attempt 1 of 1
[2025-08-16T19:16:24.880+0000] {taskinstance.py:2330} INFO - Executing <Task(_PythonDecoratedOperator): upload_to_s3> on 2025-08-16 19:16:20+00:00
[2025-08-16T19:16:24.888+0000] {standard_task_runner.py:64} INFO - Started process 163 to run task
[2025-08-16T19:16:24.893+0000] {standard_task_runner.py:90} INFO - Running: ['***', 'tasks', 'run', 'orders_pipeline', 'upload_to_s3', 'manual__2025-08-16T19:16:20+00:00', '--job-id', '46', '--raw', '--subdir', 'DAGS_FOLDER/orders_pipeline.py', '--cfg-path', '/tmp/tmp0c7rcwgb']
[2025-08-16T19:16:24.896+0000] {standard_task_runner.py:91} INFO - Job 46: Subtask upload_to_s3
[2025-08-16T19:16:24.975+0000] {task_command.py:426} INFO - Running <TaskInstance: orders_pipeline.upload_to_s3 manual__2025-08-16T19:16:20+00:00 [running]> on host 392a94efd1c1
[2025-08-16T19:16:25.139+0000] {taskinstance.py:2648} INFO - Exporting env vars: AIRFLOW_CTX_DAG_OWNER='***' AIRFLOW_CTX_DAG_ID='orders_pipeline' AIRFLOW_CTX_TASK_ID='upload_to_s3' AIRFLOW_CTX_EXECUTION_DATE='2025-08-16T19:16:20+00:00' AIRFLOW_CTX_TRY_NUMBER='1' AIRFLOW_CTX_DAG_RUN_ID='manual__2025-08-16T19:16:20+00:00'
[2025-08-16T19:16:25.140+0000] {taskinstance.py:430} INFO - ::endgroup::
[2025-08-16T19:16:25.162+0000] {credentials.py:1217} INFO - Found credentials in environment variables.
[2025-08-16T19:16:26.426+0000] {taskinstance.py:441} INFO - ::group::Post task execution logs
[2025-08-16T19:16:26.427+0000] {taskinstance.py:2905} ERROR - Task failed with exception
Traceback (most recent call last):
  File "/home/airflow/.local/lib/python3.11/site-packages/airflow/models/taskinstance.py", line 465, in _execute_task
    result = _execute_callable(context=context, **execute_callable_kwargs)
             ^^^^^^^^^^^^^^^^^^^^^^^^^^^^^^^^^^^^^^^^^^^^^^^^^^^^^^^^^^^^^
  File "/home/airflow/.local/lib/python3.11/site-packages/airflow/models/taskinstance.py", line 432, in _execute_callable
    return execute_callable(context=context, **execute_callable_kwargs)
           ^^^^^^^^^^^^^^^^^^^^^^^^^^^^^^^^^^^^^^^^^^^^^^^^^^^^^^^^^^^^
  File "/home/airflow/.local/lib/python3.11/site-packages/airflow/models/baseoperator.py", line 401, in wrapper
    return func(self, *args, **kwargs)
           ^^^^^^^^^^^^^^^^^^^^^^^^^^^
  File "/home/airflow/.local/lib/python3.11/site-packages/airflow/decorators/base.py", line 265, in execute
    return_value = super().execute(context)
                   ^^^^^^^^^^^^^^^^^^^^^^^^
  File "/home/airflow/.local/lib/python3.11/site-packages/airflow/models/baseoperator.py", line 401, in wrapper
    return func(self, *args, **kwargs)
           ^^^^^^^^^^^^^^^^^^^^^^^^^^^
  File "/home/airflow/.local/lib/python3.11/site-packages/airflow/operators/python.py", line 235, in execute
    return_value = self.execute_callable()
                   ^^^^^^^^^^^^^^^^^^^^^^^
  File "/home/airflow/.local/lib/python3.11/site-packages/airflow/operators/python.py", line 252, in execute_callable
    return self.python_callable(*self.op_args, **self.op_kwargs)
           ^^^^^^^^^^^^^^^^^^^^^^^^^^^^^^^^^^^^^^^^^^^^^^^^^^^^^
  File "/opt/airflow/dags/orders_pipeline.py", line 50, in upload_to_s3
    s3.put_object(Bucket=BUCKET, Key=payload["key"], Body=payload["body"])
  File "/home/airflow/.local/lib/python3.11/site-packages/botocore/client.py", line 602, in _api_call
    return self._make_api_call(operation_name, kwargs)
           ^^^^^^^^^^^^^^^^^^^^^^^^^^^^^^^^^^^^^^^^^^^
  File "/home/airflow/.local/lib/python3.11/site-packages/botocore/context.py", line 123, in wrapper
    return func(*args, **kwargs)
           ^^^^^^^^^^^^^^^^^^^^^
  File "/home/airflow/.local/lib/python3.11/site-packages/botocore/client.py", line 1078, in _make_api_call
    raise error_class(parsed_response, operation_name)
botocore.exceptions.ClientError: An error occurred (AccessDenied) when calling the PutObject operation: User: arn:aws:iam::657552582906:user/***-dbt-dev is not authorized to perform: s3:PutObject on resource: "arn:aws:s3:::pt-data-lab/raw-data/orders/dt=2025-08-16/orders.csv" because no identity-based policy allows the s3:PutObject action
[2025-08-16T19:16:26.446+0000] {taskinstance.py:1206} INFO - Marking task as FAILED. dag_id=orders_pipeline, task_id=upload_to_s3, run_id=manual__2025-08-16T19:16:20+00:00, execution_date=20250816T191620, start_date=20250816T191624, end_date=20250816T191626
[2025-08-16T19:16:26.466+0000] {standard_task_runner.py:110} ERROR - Failed to execute job 46 for task upload_to_s3 (An error occurred (AccessDenied) when calling the PutObject operation: User: arn:aws:iam::657552582906:user/***-dbt-dev is not authorized to perform: s3:PutObject on resource: "arn:aws:s3:::pt-data-lab/raw-data/orders/dt=2025-08-16/orders.csv" because no identity-based policy allows the s3:PutObject action; 163)
[2025-08-16T19:16:26.521+0000] {local_task_job_runner.py:243} INFO - Task exited with return code 1
[2025-08-16T19:16:26.549+0000] {taskinstance.py:3503} INFO - 0 downstream tasks scheduled from follow-on schedule check
[2025-08-16T19:16:26.552+0000] {local_task_job_runner.py:222} INFO - ::endgroup::
