[2025-08-14T16:58:59.475+0000] {local_task_job_runner.py:120} INFO - ::group::Pre task execution logs
[2025-08-14T16:58:59.506+0000] {taskinstance.py:2076} INFO - Dependencies all met for dep_context=non-requeueable deps ti=<TaskInstance: orders_pipeline.dq_parquet_gerado_no_s3 manual__2025-08-14T16:58:18.948894+00:00 [queued]>
[2025-08-14T16:58:59.520+0000] {taskinstance.py:2076} INFO - Dependencies all met for dep_context=requeueable deps ti=<TaskInstance: orders_pipeline.dq_parquet_gerado_no_s3 manual__2025-08-14T16:58:18.948894+00:00 [queued]>
[2025-08-14T16:58:59.521+0000] {taskinstance.py:2306} INFO - Starting attempt 1 of 1
[2025-08-14T16:58:59.543+0000] {taskinstance.py:2330} INFO - Executing <Task(PythonOperator): dq_parquet_gerado_no_s3> on 2025-08-14 16:58:18.948894+00:00
[2025-08-14T16:58:59.552+0000] {standard_task_runner.py:64} INFO - Started process 68 to run task
[2025-08-14T16:58:59.559+0000] {standard_task_runner.py:90} INFO - Running: ['***', 'tasks', 'run', 'orders_pipeline', 'dq_parquet_gerado_no_s3', 'manual__2025-08-14T16:58:18.948894+00:00', '--job-id', '9', '--raw', '--subdir', 'DAGS_FOLDER/orders_pipeline.py', '--cfg-path', '/tmp/tmpyirkfl6q']
[2025-08-14T16:58:59.561+0000] {standard_task_runner.py:91} INFO - Job 9: Subtask dq_parquet_gerado_no_s3
[2025-08-14T16:58:59.665+0000] {task_command.py:426} INFO - Running <TaskInstance: orders_pipeline.dq_parquet_gerado_no_s3 manual__2025-08-14T16:58:18.948894+00:00 [running]> on host fa848d464678
[2025-08-14T16:58:59.847+0000] {taskinstance.py:2648} INFO - Exporting env vars: AIRFLOW_CTX_DAG_OWNER='data-eng' AIRFLOW_CTX_DAG_ID='orders_pipeline' AIRFLOW_CTX_TASK_ID='dq_parquet_gerado_no_s3' AIRFLOW_CTX_EXECUTION_DATE='2025-08-14T16:58:18.948894+00:00' AIRFLOW_CTX_TRY_NUMBER='1' AIRFLOW_CTX_DAG_RUN_ID='manual__2025-08-14T16:58:18.948894+00:00'
[2025-08-14T16:58:59.849+0000] {taskinstance.py:430} INFO - ::endgroup::
[2025-08-14T16:58:59.906+0000] {credentials.py:1147} INFO - Found credentials in environment variables.
[2025-08-14T16:59:01.044+0000] {taskinstance.py:441} INFO - ::group::Post task execution logs
[2025-08-14T16:59:01.045+0000] {taskinstance.py:2905} ERROR - Task failed with exception
Traceback (most recent call last):
  File "/home/airflow/.local/lib/python3.11/site-packages/airflow/models/taskinstance.py", line 465, in _execute_task
    result = _execute_callable(context=context, **execute_callable_kwargs)
             ^^^^^^^^^^^^^^^^^^^^^^^^^^^^^^^^^^^^^^^^^^^^^^^^^^^^^^^^^^^^^
  File "/home/airflow/.local/lib/python3.11/site-packages/airflow/models/taskinstance.py", line 432, in _execute_callable
    return execute_callable(context=context, **execute_callable_kwargs)
           ^^^^^^^^^^^^^^^^^^^^^^^^^^^^^^^^^^^^^^^^^^^^^^^^^^^^^^^^^^^^
  File "/home/airflow/.local/lib/python3.11/site-packages/airflow/models/baseoperator.py", line 401, in wrapper
    return func(self, *args, **kwargs)
           ^^^^^^^^^^^^^^^^^^^^^^^^^^^
  File "/home/airflow/.local/lib/python3.11/site-packages/airflow/operators/python.py", line 235, in execute
    return_value = self.execute_callable()
                   ^^^^^^^^^^^^^^^^^^^^^^^
  File "/home/airflow/.local/lib/python3.11/site-packages/airflow/operators/python.py", line 252, in execute_callable
    return self.python_callable(*self.op_args, **self.op_kwargs)
           ^^^^^^^^^^^^^^^^^^^^^^^^^^^^^^^^^^^^^^^^^^^^^^^^^^^^^
  File "/opt/airflow/dags/orders_pipeline.py", line 31, in s3_has_parquet
    raise AirflowFailException(
airflow.exceptions.AirflowFailException: Nenhum .parquet gerado em s3://pt-data-lab/processed-data/orders_summary/
[2025-08-14T16:59:01.064+0000] {taskinstance.py:1206} INFO - Immediate failure requested. Marking task as FAILED. dag_id=orders_pipeline, task_id=dq_parquet_gerado_no_s3, run_id=manual__2025-08-14T16:58:18.948894+00:00, execution_date=20250814T165818, start_date=20250814T165859, end_date=20250814T165901
[2025-08-14T16:59:01.085+0000] {standard_task_runner.py:110} ERROR - Failed to execute job 9 for task dq_parquet_gerado_no_s3 (Nenhum .parquet gerado em s3://pt-data-lab/processed-data/orders_summary/; 68)
[2025-08-14T16:59:01.139+0000] {local_task_job_runner.py:243} INFO - Task exited with return code 1
[2025-08-14T16:59:01.178+0000] {taskinstance.py:3503} INFO - 0 downstream tasks scheduled from follow-on schedule check
[2025-08-14T16:59:01.181+0000] {local_task_job_runner.py:222} INFO - ::endgroup::
