[2025-08-14T18:20:38.034+0000] {local_task_job_runner.py:120} INFO - ::group::Pre task execution logs
[2025-08-14T18:20:38.083+0000] {taskinstance.py:2076} INFO - Dependencies all met for dep_context=non-requeueable deps ti=<TaskInstance: dbt_athena_pipeline.dbt_deps manual__2025-08-14T17:51:24+00:00 [queued]>
[2025-08-14T18:20:38.094+0000] {taskinstance.py:2076} INFO - Dependencies all met for dep_context=requeueable deps ti=<TaskInstance: dbt_athena_pipeline.dbt_deps manual__2025-08-14T17:51:24+00:00 [queued]>
[2025-08-14T18:20:38.094+0000] {taskinstance.py:2306} INFO - Starting attempt 1 of 1
[2025-08-14T18:20:38.118+0000] {taskinstance.py:2330} INFO - Executing <Task(BashOperator): dbt_deps> on 2025-08-14 17:51:24+00:00
[2025-08-14T18:20:38.124+0000] {standard_task_runner.py:64} INFO - Started process 117 to run task
[2025-08-14T18:20:38.130+0000] {standard_task_runner.py:90} INFO - Running: ['***', 'tasks', 'run', 'dbt_athena_pipeline', 'dbt_deps', 'manual__2025-08-14T17:51:24+00:00', '--job-id', '3', '--raw', '--subdir', 'DAGS_FOLDER/dbt_athena_pipeline.py', '--cfg-path', '/tmp/tmp8w8vqp8p']
[2025-08-14T18:20:38.132+0000] {standard_task_runner.py:91} INFO - Job 3: Subtask dbt_deps
[2025-08-14T18:20:38.212+0000] {task_command.py:426} INFO - Running <TaskInstance: dbt_athena_pipeline.dbt_deps manual__2025-08-14T17:51:24+00:00 [running]> on host 25a9e79e188f
[2025-08-14T18:20:38.369+0000] {taskinstance.py:2648} INFO - Exporting env vars: AIRFLOW_CTX_DAG_OWNER='data-eng' AIRFLOW_CTX_DAG_ID='dbt_athena_pipeline' AIRFLOW_CTX_TASK_ID='dbt_deps' AIRFLOW_CTX_EXECUTION_DATE='2025-08-14T17:51:24+00:00' AIRFLOW_CTX_TRY_NUMBER='1' AIRFLOW_CTX_DAG_RUN_ID='manual__2025-08-14T17:51:24+00:00'
[2025-08-14T18:20:38.371+0000] {taskinstance.py:430} INFO - ::endgroup::
[2025-08-14T18:20:38.438+0000] {subprocess.py:63} INFO - Tmp dir root location: /tmp
[2025-08-14T18:20:38.439+0000] {subprocess.py:75} INFO - Running command: ['/usr/bin/bash', '-c', '\n            set -euo pipefail\n            cd /opt/***/dbt\n            dbt deps --profiles-dir /opt/***/dbt/profiles\n        ']
[2025-08-14T18:20:38.461+0000] {subprocess.py:86} INFO - Output:
[2025-08-14T18:20:47.984+0000] {subprocess.py:93} INFO - [0m18:20:47  Running with dbt=1.7.19
[2025-08-14T18:20:48.583+0000] {subprocess.py:93} INFO - [0m18:20:48  Encountered an error:
[2025-08-14T18:20:48.584+0000] {subprocess.py:93} INFO - [Errno 2] No such file or directory: 'refresh_external_table.sql'
[2025-08-14T18:20:48.612+0000] {subprocess.py:93} INFO - [0m18:20:48  Traceback (most recent call last):
[2025-08-14T18:20:48.613+0000] {subprocess.py:93} INFO -   File "/home/***/.local/lib/python3.11/site-packages/dbt/cli/requires.py", line 91, in wrapper
[2025-08-14T18:20:48.619+0000] {subprocess.py:93} INFO -     result, success = func(*args, **kwargs)
[2025-08-14T18:20:48.619+0000] {subprocess.py:93} INFO -                       ^^^^^^^^^^^^^^^^^^^^^
[2025-08-14T18:20:48.620+0000] {subprocess.py:93} INFO -   File "/home/***/.local/lib/python3.11/site-packages/dbt/cli/requires.py", line 76, in wrapper
[2025-08-14T18:20:48.623+0000] {subprocess.py:93} INFO -     return func(*args, **kwargs)
[2025-08-14T18:20:48.624+0000] {subprocess.py:93} INFO -            ^^^^^^^^^^^^^^^^^^^^^
[2025-08-14T18:20:48.626+0000] {subprocess.py:93} INFO -   File "/home/***/.local/lib/python3.11/site-packages/dbt/cli/requires.py", line 152, in wrapper
[2025-08-14T18:20:48.627+0000] {subprocess.py:93} INFO -     return func(*args, **kwargs)
[2025-08-14T18:20:48.628+0000] {subprocess.py:93} INFO -            ^^^^^^^^^^^^^^^^^^^^^
[2025-08-14T18:20:48.637+0000] {subprocess.py:93} INFO -   File "/home/***/.local/lib/python3.11/site-packages/dbt/cli/requires.py", line 198, in wrapper
[2025-08-14T18:20:48.638+0000] {subprocess.py:93} INFO -     return func(*args, **kwargs)
[2025-08-14T18:20:48.638+0000] {subprocess.py:93} INFO -            ^^^^^^^^^^^^^^^^^^^^^
[2025-08-14T18:20:48.640+0000] {subprocess.py:93} INFO -   File "/home/***/.local/lib/python3.11/site-packages/dbt/cli/main.py", line 493, in deps
[2025-08-14T18:20:48.640+0000] {subprocess.py:93} INFO -     results = task.run()
[2025-08-14T18:20:48.641+0000] {subprocess.py:93} INFO -               ^^^^^^^^^^
[2025-08-14T18:20:48.641+0000] {subprocess.py:93} INFO -   File "/home/***/.local/lib/python3.11/site-packages/dbt/task/deps.py", line 228, in run
[2025-08-14T18:20:48.646+0000] {subprocess.py:93} INFO -     system.rmtree(self.project.packages_install_path)
[2025-08-14T18:20:48.647+0000] {subprocess.py:93} INFO -   File "/home/***/.local/lib/python3.11/site-packages/dbt/clients/system.py", line 570, in rmtree
[2025-08-14T18:20:48.648+0000] {subprocess.py:93} INFO -     return shutil.rmtree(path, onerror=chmod_and_retry)
[2025-08-14T18:20:48.648+0000] {subprocess.py:93} INFO -            ^^^^^^^^^^^^^^^^^^^^^^^^^^^^^^^^^^^^^^^^^^^^
[2025-08-14T18:20:48.649+0000] {subprocess.py:93} INFO -   File "/usr/local/lib/python3.11/shutil.py", line 752, in rmtree
[2025-08-14T18:20:48.650+0000] {subprocess.py:93} INFO -     _rmtree_safe_fd(fd, path, onerror)
[2025-08-14T18:20:48.650+0000] {subprocess.py:93} INFO -   File "/usr/local/lib/python3.11/shutil.py", line 672, in _rmtree_safe_fd
[2025-08-14T18:20:48.651+0000] {subprocess.py:93} INFO -     _rmtree_safe_fd(dirfd, fullname, onerror)
[2025-08-14T18:20:48.652+0000] {subprocess.py:93} INFO -   File "/usr/local/lib/python3.11/shutil.py", line 672, in _rmtree_safe_fd
[2025-08-14T18:20:48.652+0000] {subprocess.py:93} INFO -     _rmtree_safe_fd(dirfd, fullname, onerror)
[2025-08-14T18:20:48.653+0000] {subprocess.py:93} INFO -   File "/usr/local/lib/python3.11/shutil.py", line 672, in _rmtree_safe_fd
[2025-08-14T18:20:48.653+0000] {subprocess.py:93} INFO -     _rmtree_safe_fd(dirfd, fullname, onerror)
[2025-08-14T18:20:48.654+0000] {subprocess.py:93} INFO -   [Previous line repeated 1 more time]
[2025-08-14T18:20:48.654+0000] {subprocess.py:93} INFO -   File "/usr/local/lib/python3.11/shutil.py", line 703, in _rmtree_safe_fd
[2025-08-14T18:20:48.654+0000] {subprocess.py:93} INFO -     onerror(os.unlink, fullname, sys.exc_info())
[2025-08-14T18:20:48.655+0000] {subprocess.py:93} INFO -   File "/usr/local/lib/python3.11/shutil.py", line 701, in _rmtree_safe_fd
[2025-08-14T18:20:48.674+0000] {subprocess.py:93} INFO -     os.unlink(entry.name, dir_fd=topfd)
[2025-08-14T18:20:48.675+0000] {subprocess.py:93} INFO - FileNotFoundError: [Errno 2] No such file or directory: 'refresh_external_table.sql'
[2025-08-14T18:20:48.676+0000] {subprocess.py:93} INFO - 
[2025-08-14T18:20:50.499+0000] {subprocess.py:97} INFO - Command exited with return code 2
[2025-08-14T18:20:50.502+0000] {taskinstance.py:441} INFO - ::group::Post task execution logs
[2025-08-14T18:20:50.568+0000] {taskinstance.py:2905} ERROR - Task failed with exception
Traceback (most recent call last):
  File "/home/airflow/.local/lib/python3.11/site-packages/airflow/models/taskinstance.py", line 465, in _execute_task
    result = _execute_callable(context=context, **execute_callable_kwargs)
             ^^^^^^^^^^^^^^^^^^^^^^^^^^^^^^^^^^^^^^^^^^^^^^^^^^^^^^^^^^^^^
  File "/home/airflow/.local/lib/python3.11/site-packages/airflow/models/taskinstance.py", line 432, in _execute_callable
    return execute_callable(context=context, **execute_callable_kwargs)
           ^^^^^^^^^^^^^^^^^^^^^^^^^^^^^^^^^^^^^^^^^^^^^^^^^^^^^^^^^^^^
  File "/home/airflow/.local/lib/python3.11/site-packages/airflow/models/baseoperator.py", line 401, in wrapper
    return func(self, *args, **kwargs)
           ^^^^^^^^^^^^^^^^^^^^^^^^^^^
  File "/home/airflow/.local/lib/python3.11/site-packages/airflow/operators/bash.py", line 243, in execute
    raise AirflowException(
airflow.exceptions.AirflowException: Bash command failed. The command returned a non-zero exit code 2.
[2025-08-14T18:20:50.588+0000] {taskinstance.py:1206} INFO - Marking task as FAILED. dag_id=dbt_athena_pipeline, task_id=dbt_deps, run_id=manual__2025-08-14T17:51:24+00:00, execution_date=20250814T175124, start_date=20250814T182038, end_date=20250814T182050
[2025-08-14T18:20:50.872+0000] {standard_task_runner.py:110} ERROR - Failed to execute job 3 for task dbt_deps (Bash command failed. The command returned a non-zero exit code 2.; 117)
[2025-08-14T18:20:50.962+0000] {local_task_job_runner.py:243} INFO - Task exited with return code 1
[2025-08-14T18:20:51.070+0000] {taskinstance.py:3503} INFO - 0 downstream tasks scheduled from follow-on schedule check
[2025-08-14T18:20:51.086+0000] {local_task_job_runner.py:222} INFO - ::endgroup::
