[2025-08-15T18:26:15.334+0000] {local_task_job_runner.py:120} INFO - ::group::Pre task execution logs
[2025-08-15T18:26:15.374+0000] {taskinstance.py:2076} INFO - Dependencies all met for dep_context=non-requeueable deps ti=<TaskInstance: dbt_athena_pipeline.dbt_deps __airflow_temporary_run_2025-08-15T18:26:13.824381+00:00__ [queued]>
[2025-08-15T18:26:15.385+0000] {taskinstance.py:2076} INFO - Dependencies all met for dep_context=requeueable deps ti=<TaskInstance: dbt_athena_pipeline.dbt_deps __airflow_temporary_run_2025-08-15T18:26:13.824381+00:00__ [queued]>
[2025-08-15T18:26:15.385+0000] {taskinstance.py:2306} INFO - Starting attempt 1 of 1
[2025-08-15T18:26:15.406+0000] {taskinstance.py:2330} INFO - Executing <Task(BashOperator): dbt_deps> on 2025-08-15 00:00:00+00:00
[2025-08-15T18:26:15.413+0000] {standard_task_runner.py:64} INFO - Started process 241 to run task
[2025-08-15T18:26:15.420+0000] {standard_task_runner.py:90} INFO - Running: ['***', 'tasks', 'run', 'dbt_athena_pipeline', 'dbt_deps', '__***_temporary_run_2025-08-15T18:26:13.824381+00:00__', '--job-id', '67', '--raw', '--subdir', 'DAGS_FOLDER/dbt_athena_pipeline.py', '--cfg-path', '/tmp/tmp6qv03ost']
[2025-08-15T18:26:15.423+0000] {standard_task_runner.py:91} INFO - Job 67: Subtask dbt_deps
[2025-08-15T18:26:15.531+0000] {task_command.py:426} INFO - Running <TaskInstance: dbt_athena_pipeline.dbt_deps __airflow_temporary_run_2025-08-15T18:26:13.824381+00:00__ [running]> on host e1203d83167e
[2025-08-15T18:26:15.706+0000] {taskinstance.py:2648} INFO - Exporting env vars: AIRFLOW_CTX_DAG_OWNER='***' AIRFLOW_CTX_DAG_ID='dbt_athena_pipeline' AIRFLOW_CTX_TASK_ID='dbt_deps' AIRFLOW_CTX_EXECUTION_DATE='2025-08-15T00:00:00+00:00' AIRFLOW_CTX_TRY_NUMBER='1' AIRFLOW_CTX_DAG_RUN_ID='__***_temporary_run_2025-08-15T18:26:13.824381+00:00__'
[2025-08-15T18:26:15.709+0000] {taskinstance.py:430} INFO - ::endgroup::
[2025-08-15T18:26:15.732+0000] {subprocess.py:63} INFO - Tmp dir root location: /tmp
[2025-08-15T18:26:15.733+0000] {subprocess.py:75} INFO - Running command: ['/usr/bin/bash', '-c', 'set -e -o pipefail -x; cd /opt/***/dbt; echo "ENV S3_BUCKET=$S3_BUCKET ATHENA_DB=$ATHENA_DB AWS_DEFAULT_REGION=$AWS_DEFAULT_REGION"; /home/***/.local/bin/dbt --no-use-colors deps --profiles-dir /opt/***/.dbt -v']
[2025-08-15T18:26:15.753+0000] {subprocess.py:86} INFO - Output:
[2025-08-15T18:26:15.755+0000] {subprocess.py:93} INFO - + cd /opt/***/dbt
[2025-08-15T18:26:15.756+0000] {subprocess.py:93} INFO - + echo 'ENV S3_BUCKET=pt-data-lab ATHENA_DB=analytics AWS_DEFAULT_REGION=us-east-2'
[2025-08-15T18:26:15.757+0000] {subprocess.py:93} INFO - ENV S3_BUCKET=pt-data-lab ATHENA_DB=analytics AWS_DEFAULT_REGION=us-east-2
[2025-08-15T18:26:15.757+0000] {subprocess.py:93} INFO - + /home/***/.local/bin/dbt --no-use-colors deps --profiles-dir /opt/***/.dbt -v
[2025-08-15T18:26:20.975+0000] {subprocess.py:93} INFO - Core:
[2025-08-15T18:26:20.976+0000] {subprocess.py:93} INFO -   - installed: 1.9.2
[2025-08-15T18:26:20.976+0000] {subprocess.py:93} INFO -   - latest:    1.10.8 - Update available!
[2025-08-15T18:26:20.977+0000] {subprocess.py:93} INFO - 
[2025-08-15T18:26:20.977+0000] {subprocess.py:93} INFO -   Your version of dbt-core is out of date!
[2025-08-15T18:26:20.977+0000] {subprocess.py:93} INFO -   You can find instructions for upgrading here:
[2025-08-15T18:26:20.978+0000] {subprocess.py:93} INFO -   https://docs.getdbt.com/docs/installation
[2025-08-15T18:26:20.979+0000] {subprocess.py:93} INFO - 
[2025-08-15T18:26:20.979+0000] {subprocess.py:93} INFO - Plugins:
[2025-08-15T18:26:20.980+0000] {subprocess.py:93} INFO -   - athena: 1.9.4 - Up to date!
[2025-08-15T18:26:20.980+0000] {subprocess.py:93} INFO - 
[2025-08-15T18:26:20.980+0000] {subprocess.py:93} INFO - 
[2025-08-15T18:26:21.383+0000] {subprocess.py:97} INFO - Command exited with return code 0
[2025-08-15T18:26:21.384+0000] {taskinstance.py:441} INFO - ::group::Post task execution logs
[2025-08-15T18:26:21.414+0000] {taskinstance.py:2905} ERROR - Task failed with exception
Traceback (most recent call last):
  File "/home/airflow/.local/lib/python3.11/site-packages/airflow/models/taskinstance.py", line 486, in _execute_task
    task_instance.xcom_push(key=XCOM_RETURN_KEY, value=xcom_value, session=session)
  File "/home/airflow/.local/lib/python3.11/site-packages/airflow/utils/session.py", line 76, in wrapper
    return func(*args, **kwargs)
           ^^^^^^^^^^^^^^^^^^^^^
  File "/home/airflow/.local/lib/python3.11/site-packages/airflow/models/taskinstance.py", line 3197, in xcom_push
    XCom.set(
  File "/home/airflow/.local/lib/python3.11/site-packages/airflow/utils/session.py", line 76, in wrapper
    return func(*args, **kwargs)
           ^^^^^^^^^^^^^^^^^^^^^
  File "/home/airflow/.local/lib/python3.11/site-packages/airflow/models/xcom.py", line 223, in set
    raise ValueError(f"DAG run not found on DAG {dag_id!r} with ID {run_id!r}")
ValueError: DAG run not found on DAG 'dbt_athena_pipeline' with ID '__***_temporary_run_2025-08-15T18:26:13.824381+00:00__'
[2025-08-15T18:26:21.435+0000] {taskinstance.py:1206} INFO - Marking task as FAILED. dag_id=dbt_athena_pipeline, task_id=dbt_deps, run_id=__***_temporary_run_2025-08-15T18:26:13.824381+00:00__, execution_date=20250815T000000, start_date=20250815T182615, end_date=20250815T182621
[2025-08-15T18:26:21.459+0000] {standard_task_runner.py:110} ERROR - Failed to execute job 67 for task dbt_deps ((psycopg2.errors.ForeignKeyViolation) insert or update on table "task_fail" violates foreign key constraint "task_fail_ti_fkey"
DETAIL:  Key (dag_id, task_id, run_id, map_index)=(dbt_athena_pipeline, dbt_deps, __airflow_temporary_run_2025-08-15T18:26:13.824381+00:00__, -1) is not present in table "task_instance".

[SQL: INSERT INTO task_fail (task_id, dag_id, run_id, map_index, start_date, end_date, duration) VALUES (%(task_id)s, %(dag_id)s, %(run_id)s, %(map_index)s, %(start_date)s, %(end_date)s, %(duration)s) RETURNING task_fail.id]
[parameters: {'task_id': 'dbt_deps', 'dag_id': 'dbt_athena_pipeline', 'run_id': '__airflow_temporary_run_2025-08-15T18:26:13.824381+00:00__', 'map_index': -1, 'start_date': datetime.datetime(2025, 8, 15, 18, 26, 15, 374693, tzinfo=Timezone('UTC')), 'end_date': datetime.datetime(2025, 8, 15, 18, 26, 21, 433841, tzinfo=Timezone('UTC')), 'duration': 6}]
(Background on this error at: https://sqlalche.me/e/14/gkpj); 241)
[2025-08-15T18:26:21.492+0000] {local_task_job_runner.py:243} INFO - Task exited with return code 1
[2025-08-15T18:26:21.513+0000] {local_task_job_runner.py:222} INFO - ::endgroup::
