[2025-08-14T18:21:06.935+0000] {local_task_job_runner.py:120} INFO - ::group::Pre task execution logs
[2025-08-14T18:21:06.992+0000] {taskinstance.py:2076} INFO - Dependencies all met for dep_context=non-requeueable deps ti=<TaskInstance: dbt_athena_pipeline.dbt_run manual__2025-08-14T18:20:36.033121+00:00 [queued]>
[2025-08-14T18:21:07.022+0000] {taskinstance.py:2076} INFO - Dependencies all met for dep_context=requeueable deps ti=<TaskInstance: dbt_athena_pipeline.dbt_run manual__2025-08-14T18:20:36.033121+00:00 [queued]>
[2025-08-14T18:21:07.023+0000] {taskinstance.py:2306} INFO - Starting attempt 1 of 1
[2025-08-14T18:21:07.057+0000] {taskinstance.py:2330} INFO - Executing <Task(BashOperator): dbt_run> on 2025-08-14 18:20:36.033121+00:00
[2025-08-14T18:21:07.065+0000] {standard_task_runner.py:64} INFO - Started process 162 to run task
[2025-08-14T18:21:07.071+0000] {standard_task_runner.py:90} INFO - Running: ['***', 'tasks', 'run', 'dbt_athena_pipeline', 'dbt_run', 'manual__2025-08-14T18:20:36.033121+00:00', '--job-id', '17', '--raw', '--subdir', 'DAGS_FOLDER/dbt_athena_pipeline.py', '--cfg-path', '/tmp/tmpwwpu7qyt']
[2025-08-14T18:21:07.073+0000] {standard_task_runner.py:91} INFO - Job 17: Subtask dbt_run
[2025-08-14T18:21:07.190+0000] {task_command.py:426} INFO - Running <TaskInstance: dbt_athena_pipeline.dbt_run manual__2025-08-14T18:20:36.033121+00:00 [running]> on host 25a9e79e188f
[2025-08-14T18:21:07.416+0000] {taskinstance.py:2648} INFO - Exporting env vars: AIRFLOW_CTX_DAG_OWNER='data-eng' AIRFLOW_CTX_DAG_ID='dbt_athena_pipeline' AIRFLOW_CTX_TASK_ID='dbt_run' AIRFLOW_CTX_EXECUTION_DATE='2025-08-14T18:20:36.033121+00:00' AIRFLOW_CTX_TRY_NUMBER='1' AIRFLOW_CTX_DAG_RUN_ID='manual__2025-08-14T18:20:36.033121+00:00'
[2025-08-14T18:21:07.418+0000] {taskinstance.py:430} INFO - ::endgroup::
[2025-08-14T18:21:07.446+0000] {subprocess.py:63} INFO - Tmp dir root location: /tmp
[2025-08-14T18:21:07.450+0000] {subprocess.py:75} INFO - Running command: ['/usr/bin/bash', '-c', '\n            set -euo pipefail\n            cd /opt/***/dbt\n            dbt run --profiles-dir /opt/***/dbt/profiles --threads 4\n        ']
[2025-08-14T18:21:07.473+0000] {subprocess.py:86} INFO - Output:
[2025-08-14T18:21:14.223+0000] {subprocess.py:93} INFO - [0m18:21:14  Running with dbt=1.7.19
[2025-08-14T18:21:16.376+0000] {subprocess.py:93} INFO - [0m18:21:16  Registered adapter: athena=1.7.2
[2025-08-14T18:21:16.645+0000] {subprocess.py:93} INFO - [0m18:21:16  Found 1 model, 1 source, 0 exposures, 0 metrics, 477 macros, 0 groups, 0 semantic models
[2025-08-14T18:21:16.653+0000] {subprocess.py:93} INFO - [0m18:21:16
[2025-08-14T18:21:21.104+0000] {subprocess.py:93} INFO - [0m18:21:21  Concurrency: 4 threads (target='dev')
[2025-08-14T18:21:21.106+0000] {subprocess.py:93} INFO - [0m18:21:21
[2025-08-14T18:21:21.131+0000] {subprocess.py:93} INFO - [0m18:21:21  1 of 1 START sql table model analytics.processed_orders ........................ [RUN]
[2025-08-14T18:21:57.716+0000] {subprocess.py:93} INFO - [0m18:21:57  [31mUnhandled error while executing [0m
[2025-08-14T18:21:57.717+0000] {subprocess.py:93} INFO - SCHEMA_NOT_FOUND: line 14:3: Schema '${athena_db}' does not exist. You may need to manually clean the data at location 's3://pt-data-lab/athena-staging/tables/55e22dc5-d83c-4636-8ea0-2e7c040646b8' before retrying. Athena will not delete data in your account.
[2025-08-14T18:21:57.738+0000] {subprocess.py:93} INFO - [0m18:21:57  1 of 1 ERROR creating sql table model analytics.processed_orders ............... [[31mERROR[0m in 36.60s]
[2025-08-14T18:21:57.754+0000] {subprocess.py:93} INFO - [0m18:21:57
[2025-08-14T18:21:57.755+0000] {subprocess.py:93} INFO - [0m18:21:57  Finished running 1 table model in 0 hours 0 minutes and 41.10 seconds (41.10s).
[2025-08-14T18:21:57.804+0000] {subprocess.py:93} INFO - [0m18:21:57
[2025-08-14T18:21:57.805+0000] {subprocess.py:93} INFO - [0m18:21:57  [31mCompleted with 1 error and 0 warnings:[0m
[2025-08-14T18:21:57.806+0000] {subprocess.py:93} INFO - [0m18:21:57
[2025-08-14T18:21:57.807+0000] {subprocess.py:93} INFO - [0m18:21:57    SCHEMA_NOT_FOUND: line 14:3: Schema '${athena_db}' does not exist. You may need to manually clean the data at location 's3://pt-data-lab/athena-staging/tables/55e22dc5-d83c-4636-8ea0-2e7c040646b8' before retrying. Athena will not delete data in your account.
[2025-08-14T18:21:57.808+0000] {subprocess.py:93} INFO - [0m18:21:57
[2025-08-14T18:21:57.810+0000] {subprocess.py:93} INFO - [0m18:21:57  Done. PASS=0 WARN=0 ERROR=1 SKIP=0 TOTAL=1
[2025-08-14T18:21:59.140+0000] {subprocess.py:97} INFO - Command exited with return code 1
[2025-08-14T18:21:59.141+0000] {taskinstance.py:441} INFO - ::group::Post task execution logs
[2025-08-14T18:21:59.164+0000] {taskinstance.py:2905} ERROR - Task failed with exception
Traceback (most recent call last):
  File "/home/airflow/.local/lib/python3.11/site-packages/airflow/models/taskinstance.py", line 465, in _execute_task
    result = _execute_callable(context=context, **execute_callable_kwargs)
             ^^^^^^^^^^^^^^^^^^^^^^^^^^^^^^^^^^^^^^^^^^^^^^^^^^^^^^^^^^^^^
  File "/home/airflow/.local/lib/python3.11/site-packages/airflow/models/taskinstance.py", line 432, in _execute_callable
    return execute_callable(context=context, **execute_callable_kwargs)
           ^^^^^^^^^^^^^^^^^^^^^^^^^^^^^^^^^^^^^^^^^^^^^^^^^^^^^^^^^^^^
  File "/home/airflow/.local/lib/python3.11/site-packages/airflow/models/baseoperator.py", line 401, in wrapper
    return func(self, *args, **kwargs)
           ^^^^^^^^^^^^^^^^^^^^^^^^^^^
  File "/home/airflow/.local/lib/python3.11/site-packages/airflow/operators/bash.py", line 243, in execute
    raise AirflowException(
airflow.exceptions.AirflowException: Bash command failed. The command returned a non-zero exit code 1.
[2025-08-14T18:21:59.173+0000] {taskinstance.py:1206} INFO - Marking task as FAILED. dag_id=dbt_athena_pipeline, task_id=dbt_run, run_id=manual__2025-08-14T18:20:36.033121+00:00, execution_date=20250814T182036, start_date=20250814T182106, end_date=20250814T182159
[2025-08-14T18:21:59.199+0000] {standard_task_runner.py:110} ERROR - Failed to execute job 17 for task dbt_run (Bash command failed. The command returned a non-zero exit code 1.; 162)
[2025-08-14T18:21:59.255+0000] {local_task_job_runner.py:243} INFO - Task exited with return code 1
[2025-08-14T18:21:59.285+0000] {taskinstance.py:3503} INFO - 0 downstream tasks scheduled from follow-on schedule check
[2025-08-14T18:21:59.291+0000] {local_task_job_runner.py:222} INFO - ::endgroup::
